<?xml version="1.0" encoding="utf-8"?>
<!-- This URDF was automatically created by SolidWorks to URDF Exporter! Originally created by Stephen Brawner (brawner@gmail.com) 
     Commit Version: 1.6.0-1-g15f4949  Build Version: 1.6.7594.29634
     For more information, please see http://wiki.ros.org/sw_urdf_exporter -->
<robot
  name="agvcar">
  <link
    name="base_link">
    <inertial>
      <origin
        xyz="0.0015713 -0.00080147 0.053517"
        rpy="0 0 0" />
      <mass
        value="8.0442" />
      <inertia
        ixx="0.048158"
        ixy="2.0276E-05"
        ixz="2.1723E-07"
        iyy="0.077509"
        iyz="-7.974E-07"
        izz="0.11857" />
    </inertial>
    <visual>
      <origin
        xyz="0 0 0"
        rpy="0 0 0" />
      <geometry>
        <mesh
          filename="package://agvcar/meshes/base_link.STL" />
      </geometry>
      <material
        name="">
        <color
          rgba="0.75294 0.75294 0.75294 1" />
      </material>
    </visual>
    <collision>
      <origin
        xyz="0 0 0"
        rpy="0 0 0" />
      <geometry>
        <mesh
          filename="package://agvcar/meshes/base_link.STL" />
      </geometry>
    </collision>
  </link>
  <link
    name="wheel_linkr">
    <inertial>
      <origin
        xyz="-1.6402E-17 0.01929 -6.3682E-06"
        rpy="0 0 0" />
      <mass
        value="0.97528" />
      <inertia
        ixx="0.0014416"
        ixy="-1.0983E-18"
        ixz="-4.8129E-22"
        iyy="0.0026015"
        iyz="6.8161E-09"
        izz="0.0014416" />
    </inertial>
    <visual>
      <origin
        xyz="0 0 0"
        rpy="0 0 0" />
      <geometry>
        <mesh
          filename="package://agvcar/meshes/wheel_linkr.STL" />
      </geometry>
      <material
        name="">
        <color
          rgba="1 1 1 1" />
      </material>
    </visual>
    <collision>
      <origin
        xyz="0 0 0"
        rpy="0 0 0" />
      <geometry>
        <mesh
          filename="package://agvcar/meshes/wheel_linkr.STL" />
      </geometry>
    </collision>
  </link>
  <joint
    name="joint1"
    type="continuous">
    <origin
      xyz="0.00077321 -0.1676 0.00305"
      rpy="0 0 0" />
    <parent
      link="base_link" />
    <child
      link="wheel_linkr" />
    <axis
      xyz="0 1 0" />
  </joint>
  <link
    name="wheel_linkl">
    <inertial>
      <origin
        xyz="3.23889780528675E-16 -0.0341899792438043 -6.36824230722255E-06"
        rpy="0 0 0" />
      <mass
        value="0.975276702669122" />
      <inertia
        ixx="0.0014415826428145"
        ixy="-1.11861270772928E-18"
        ixz="5.47113304489091E-22"
        iyy="0.0026014997834374"
        iyz="-6.81614475929063E-09"
        izz="0.00144162042998264" />
    </inertial>
    <visual>
      <origin
        xyz="0 0 0"
        rpy="0 0 0" />
      <geometry>
        <mesh
          filename="package://agvcar/meshes/wheel_linkl.STL" />
      </geometry>
      <material
        name="">
        <color
          rgba="1 1 1 1" />
      </material>
    </visual>
    <collision>
      <origin
        xyz="0 0 0"
        rpy="0 0 0" />
      <geometry>
        <mesh
          filename="package://agvcar/meshes/wheel_linkl.STL" />
      </geometry>
    </collision>
  </link>
  <joint
    name="joint2"
    type="continuous">
    <origin
      xyz="0.00077321 0.1825 0.00305"
      rpy="0 0 0" />
    <parent
      link="base_link" />
    <child
      link="wheel_linkl" />
    <axis
      xyz="0 1 0" />
  </joint>
  <link
    name="lidar_link">
    <inertial>
      <origin
        xyz="0.0133625593825962 0.000561225224982004 0.001213203484491"
        rpy="0 0 0" />
      <mass
        value="0.0716630788469335" />
      <inertia
        ixx="1.8018146584112E-05"
        ixy="5.92053205373987E-07"
        ixz="2.9454242447531E-07"
        iyy="2.3889220590142E-05"
        iyz="-2.7945777525098E-09"
        izz="3.94339872238935E-05" />
    </inertial>
    <visual>
      <origin
        xyz="0 0 0"
        rpy="0 0 0" />
      <geometry>
        <!-- <mesh
          filename="package://agvcar/meshes/lidar_link.STL" /> -->
                  <cylinder radius="0.12" length="0.02"/>
      </geometry>
      <material
        name="">
        <color
          rgba="0.752941176470588 0.752941176470588 0.752941176470588 1" />
      </material>
    </visual>
    <collision>
      <origin
        xyz="0 0 0"
        rpy="0 0 0" />
      <geometry>
        <!-- <mesh
          filename="package://agvcar/meshes/lidar_link.STL" /> -->
                    <cylinder radius="0.12" length="0.02"/>
      </geometry>
    </collision>
  </link>
  <joint
    name="joint4"
    type="fixed">
    <origin
      xyz="-0.024296 -0.00036246 0.09"
      rpy="0 0 0" />
    <parent
      link="base_link" />
    <child
      link="lidar_link" />
    <axis
      xyz="0 0 0" />
  </joint>
  <link
    name="imu_link">
    <inertial>
      <origin
        xyz="0.00110854842932509 0.000207236030641384 0.000412557390234325"
        rpy="0 0 0" />
      <mass
        value="0.0174472201901509" />
      <inertia
        ixx="9.17290327815907E-06"
        ixy="-1.46537185672713E-08"
        ixz="1.00361368145288E-09"
        iyy="4.53867028245448E-06"
        iyz="-1.83257391037148E-10"
        izz="1.36659329430745E-05" />
    </inertial>
    <visual>
      <origin
        xyz="0 0 0"
        rpy="0 0 0" />
      <geometry>
        <mesh
          filename="package://agvcar/meshes/imu_link.STL" />
      </geometry>
      <material
        name="">
        <color
          rgba="0.8 0.8 0.8 1" />
      </material>
    </visual>
    <collision>
      <origin
        xyz="0 0 0"
        rpy="0 0 0" />
      <geometry>
        <mesh
          filename="package://agvcar/meshes/imu_link.STL" />
      </geometry>
    </collision>
  </link>
  <joint
    name="joint3"
    type="fixed">
    <origin
      xyz="-0.084184 0.00018458 0.0498"
      rpy="0 0 0" />
    <parent
      link="base_link" />
    <child
      link="imu_link" />
    <axis
      xyz="0 0 0" />
  </joint>
  <link
    name="deep_link">
    <inertial>
      <origin
        xyz="0 0 0"
        rpy="0 0 0" />
      <mass
        value="0" />
      <inertia
        ixx="0"
        ixy="0"
        ixz="0"
        iyy="0"
        iyz="0"
        izz="0" />
    </inertial>
    <visual>
      <origin
        xyz="0 0 0"
        rpy="0 0 0" />
      <geometry>
        <!-- <mesh
          filename="package://agvcar/meshes/deep_link.STL" /> -->
                    <box size="0.045 0.15 0.05"/>
      </geometry>
      <material
        name="">
        <color
          rgba="1 1 1 1" />
      </material>
    </visual>
    <collision>
      <origin
        xyz="0 0 0"
        rpy="0 0 0" />
      <geometry>
        <!-- <mesh
          filename="package://agvcar/meshes/deep_link.STL" /> -->
                    <box size="0.045 0.15 0.05"/>
      </geometry>
    </collision>
  </link>
  <joint
    name="joint5"
    type="fixed">
    <origin
      xyz="0.25652 -0.00051396 0.073248"
      rpy="0 0 0" />
    <parent
      link="base_link" />
    <child
      link="deep_link" />
    <axis
      xyz="0 0 0" />
  </joint>
</robot>